# 🔧 إصلاح خطأ AttributeError في Authentication

## ❌ المشكلة

```python
AttributeError: tenant_test_db_fix
```

عند محاولة حذف connection:
```python
del connections[db_alias]
```

---

## ✅ الحل

### قبل:
```python
if db_alias not in settings.DATABASES:
    db_config = get_tenant_db_config(tenant.subdomain)
    settings.DATABASES[db_alias] = db_config
    # Force connection to be reloaded
    if db_alias in connections:
        del connections[db_alias]  # ❌ خطأ! connection غير موجود
```

### بعد:
```python
if db_alias not in settings.DATABASES:
    db_config = get_tenant_db_config(tenant.subdomain)
    settings.DATABASES[db_alias] = db_config
    # Also register in connections.databases
    connections.databases[db_alias] = db_config
    
    # Close existing connection if any (safe way)
    if hasattr(connections._connections, db_alias):
        try:
            conn = getattr(connections._connections, db_alias)
            conn.close()
        except:
            pass
        try:
            delattr(connections._connections, db_alias)
        except:
            pass
```

---

## 🎯 التغييرات

1. ✅ **تسجيل في `connections.databases`** - يضمن أن Django يعرف الـ database
2. ✅ **استخدام `hasattr()`** - يتحقق من وجود connection قبل الحذف
3. ✅ **استخدام `try/except`** - يتجاهل الأخطاء عند الإغلاق/الحذف
4. ✅ **استخدام `delattr()`** - طريقة آمنة للحذف

---

## 📝 الملف المُعدّل

- ✅ `hr_management/authentication.py` - lines 49-63

---

## 🧪 الاختبار

```bash
# شغّل server
python manage.py runserver

# في terminal آخر
curl -X POST http://localhost:8000/api/token/ \
  -H "Content-Type: application/json" \
  -H "X-Tenant-Subdomain: testc" \
  -d '{"username":"admin","password":"admin123"}'
```

**النتيجة المتوقعة:**
```json
{
  "access": "eyJ0eXAiOiJKV1Qi...",
  "refresh": "eyJ0eXAiOiJKV1Qi...",
  "tenant": "testc",
  "user_id": 1,
  "username": "admin"
}
```

---

**الحالة:** ✅ مُصلح  
**التاريخ:** October 22, 2025
